<?xml version="1.0"?>
<robot name="hermes">

    <!-- Materials and base footprint remain unchanged -->
    <material name="grey">
        <color rgba="0.7 0.7 0.7 1"/>
    </material>

    <link name="base_footprint">
        <origin xyz="0 0 0"/>
    </link>    
    
    <!-- Base link -->
    <link name="base_link">
        <inertial>
            <mass value="25.0"/>
            <inertia ixx="0.5" ixy="0.0" ixz="0.0" iyy="0.5" iyz="0.0" izz="0.1"/>
        </inertial>
        <visual>
            <origin xyz="-0.00017382192779770617736 0.44233349576524649827 -0.0084281873210687308084" rpy="0 0 -1.5707963267948966" />
            <geometry>
                <mesh filename="package://hermes_urdf/urdf/kere.stl"/>
            </geometry>
            <material name="kere_material">
                <color rgba="0.61568627 0.81176471 0.92941176 1.0"/>
            </material>
        </visual>
        <collision>
            <origin xyz="-0.00017382192779770617736 0.44233349576524649827 -0.0084281873210687308084" rpy="0 0 -1.5707963267948966" />
            <geometry>
                <mesh filename="package://hermes_urdf/urdf/kere.stl"/>
            </geometry>
        </collision>
    </link>

    <!-- Rear right wheel -->
    <link name="rear_right_wheel">
        <inertial>
            <mass value="3.0"/>
            <inertia ixx="0.1" ixy="0.0" ixz="0.0" iyy="0.1" iyz="0.0" izz="0.05"/>
        </inertial>
        <visual>
            <origin xyz="0 0 0" rpy="0 0 0" />
            <geometry>
                <mesh filename="package://hermes_urdf/urdf/rehv_tagumine.stl"/>
            </geometry>
            <material name="rehv1_material">
                <color rgba="0.61568627 0.81176471 0.92941176 1.0"/>
            </material>
        </visual>
        <collision>
            <origin xyz="0 0 0" rpy="0 0 0" />
            <geometry>
                <mesh filename="package://hermes_urdf/urdf/rehv_tagumine.stl"/>
            </geometry>
        </collision>
    </link>

    <joint name="base_rear_right_wheel_joint" type="continuous">
        <parent link="base_link"/>
        <child link="rear_right_wheel"/>
        <origin xyz="0.25732617807220243 0.8815534957652464 0.001571812678931278" rpy="1.5707963267948966 1.5707963267948966 0" />
        <axis xyz="0 -1 0"/>
    </joint>

    <!-- Rear left wheel -->
    <link name="rear_left_wheel">
        <inertial>
            <mass value="3.0"/>
            <inertia ixx="0.1" ixy="0.0" ixz="0.0" iyy="0.1" iyz="0.0" izz="0.05"/>
        </inertial>
        <visual>
            <origin xyz="0 0 0" rpy="0 0 0" />
            <geometry>
                <mesh filename="package://hermes_urdf/urdf/rehv_tagumine.stl"/>
            </geometry>
            <material name="rehv1_material">
                <color rgba="0.61568627 0.81176471 0.92941176 1.0"/>
            </material>
        </visual>
        <collision>
            <origin xyz="0 0 0" rpy="0 0 0" />
            <geometry>
                <mesh filename="package://hermes_urdf/urdf/rehv_tagumine.stl"/>
            </geometry>
        </collision>
    </link>

    <joint name="base_rear_left_wheel_joint" type="continuous">
        <parent link="base_link"/>
        <child link="rear_left_wheel"/>
        <origin xyz="-0.20767382192779785 0.8815534957652466 0.0015718126789312503" rpy="1.5707963267948966 1.5707963267948966 0" />
        <axis xyz="0 -1 0" />
    </joint>

    <!-- Front left wheel -->
    <link name="front_left_wheel">
        <inertial>
            <mass value="10.0"/>
            <inertia ixx="0.1" ixy="0.0" ixz="0.0" iyy="0.1" iyz="0.0" izz="0.05"/>
        </inertial>
        <visual>
            <origin xyz="0 0 0" rpy="0 0 1.58" />
            <geometry>
                <mesh filename="package://hermes_urdf/urdf/rehv.stl"/>
            </geometry>
            <material name="rehv1_material">
                <color rgba="0.61568627 0.81176471 0.92941176 1.0"/>
            </material>
        </visual>
        <collision>
            <origin xyz="0 0 0" rpy="0 0 1.58" />
            <geometry>
                <mesh filename="package://hermes_urdf/urdf/rehv.stl"/>
            </geometry>
        </collision>
    </link>

    <joint name="base_front_left_wheel_joint" type="continuous">
        <parent link="liigend"/>
        <child link="front_left_wheel"/>
        <origin xyz="0.30257617807220233 -0.00024642929502571853 -0.0034281873210687194" rpy="0 0 3.141592653589793" />
        <axis xyz="-1 0 0" />
    </joint>

    <!-- Front right wheel -->
    <link name="front_right_wheel">
        <inertial>
            <mass value="10.0"/>
            <inertia ixx="0.1" ixy="0.0" ixz="0.0" iyy="0.1" iyz="0.0" izz="0.05"/>
        </inertial>
        <visual>
            <origin xyz="0 0 0" rpy="0 0 1.583" />
            <geometry>
                <mesh filename="package://hermes_urdf/urdf/rehv.stl"/>
            </geometry>
            <material name="rehv1_material">
                <color rgba="0.61568627 0.81176471 0.92941176 1.0"/>
            </material>
        </visual>
        <collision>
            <origin xyz="0 0 0" rpy="0 0 1.583" />
            <geometry>
                <mesh filename="package://hermes_urdf/urdf/rehv.stl"/>
            </geometry>
        </collision>
    </link>

    <joint name="base_front_right_wheel_joint" type="continuous">
        <parent link="liigend"/>
        <child link="front_right_wheel"/>
        <origin xyz="-0.3029238219277977 -0.00024642929502571853 -0.0034281873210687333" rpy="0 0 0" />
        <axis xyz="-1 0 0" />
    </joint>

    <!-- Steering mechanism (liigend) -->
    <link name="liigend">
        <inertial>
            <mass value="2.0"/>
            <inertia ixx="0.5" ixy="0.0" ixz="0.0" iyy="0.5" iyz="0.0" izz="0.1"/>
        </inertial>
        <visual>
            <origin xyz="0 0 0" rpy="0 0 0" />
            <geometry>
                <mesh filename="package://hermes_urdf/urdf/liigend.stl"/>
            </geometry>
            <material name="liigend_material">
                <color rgba="0.61568627 0.81176471 0.92941176 1.0"/>
            </material>
        </visual>
    </link>

    <joint name="liigend_to_kere_joint" type="revolute">
        <parent link="base_link"/>
        <child link="liigend"/>
        <origin xyz="-0.00017382192779770433 -0.00024642929502571853 -0.0034281873210687264" rpy="0 0 0" />
        <axis xyz="0 0 1"/>
        <limit lower="-0.7854" upper="0.7854" effort="50" velocity="2"/>
    </joint>

    <!-- Base joint -->
    <joint name="base_joint" type="fixed">
        <parent link="base_footprint"/>
        <child link="base_link"/>
        <origin xyz="0 0 0.1" rpy="0 0 1.57"/>
    </joint>

<<<<<<< HEAD
    <!-- IMU link -->
=======
    
>>>>>>> 983780703ae1681e6eebcb8c4634135f8974e252
    <link name="imu_link">
    </link>

    <joint name="base_link_to_imu" type="fixed">
        <parent link="base_link"/>
        <child link="imu_link"/>
        <origin xyz="-0.00032976124091513292 -0.09157889848896106 0.38657181267893126" rpy="0 0 -3.141592653589793" />
    </joint>

    <!-- ros2_control configuration -->
    <ros2_control name="MyRobotHardware" type="system">
        <hardware>
            <plugin>fake_components/GenericSystem</plugin>
            <param name="example_param">example_value</param>
        </hardware>

        <!-- Rear left wheel joint -->
        <joint name="base_front_left_wheel_joint">
            <command_interface name="velocity">
                <param name="min">-10</param>
                <param name="max">10</param>
            </command_interface>
            <state_interface name="position"/>
            <state_interface name="velocity"/>
        </joint>

        <!-- Rear right wheel joint -->
        <joint name="base_front_right_wheel_joint">
            <command_interface name="velocity">
                <param name="min">-10</param>
                <param name="max">10</param>
            </command_interface>
            <state_interface name="position"/>
            <state_interface name="velocity"/>
        </joint>

        <joint name="liigend_to_kere_joint">
            <command_interface name="position">
                <param name="min">-0.7854</param> <!-- -45 degrees in radians -->
                <param name="max">0.7854</param>  <!-- 45 degrees in radians -->
             </command_interface>
            <state_interface name="position"/>
            <state_interface name="velocity"/>
        </joint>
        
    </ros2_control>

    <!-- Additional materials and links (e.g., for LIDAR) remain unchanged -->
    
    <material name="ld19 color">
        <color rgba="0.2313725490196078538 0.38039215686274507888 0.7058823529411765163 1.0"/>
    </material>
    
    <link name="ld19">
        <inertial>
            <mass value="2.0"/>
            <inertia ixx="0.5" ixy="0.0" ixz="0.0" iyy="0.5" iyz="0.0" izz="0.5"/>
        </inertial>
        <visual>
            <origin xyz="0 0 0" rpy="0 0 0" />
            <geometry>
                <mesh filename="package://hermes_urdf/urdf/ld19.stl"/>
            </geometry>
            <material name="ld19_material">
                <color rgba="0.2313725490196078538 0.38039215686274507888 0.7058823529411765163 1.0"/>
            </material>
        </visual>
    </link>

    <joint name="base_lidar_joint" type="fixed">
        <parent link="base_link"/>
        <child link="ld19"/>
        <origin xyz="-0.00032976124091513292491 -0.091578898488961058 0.3865718126789312592" rpy="6.3108872417680804303e-30 -2.9537602700216738211e-30 -3.141592653589793116" />
    </joint>
    
    <link name="camera_link">
        <inertial>
            <mass value="0.1"/>  <!-- Give it a small mass to avoid issues -->
            <inertia ixx="0.0001" ixy="0.0" ixz="0.0" iyy="0.0001" iyz="0.0" izz="0.0001"/>
        </inertial>
    </link>
    
    <joint name="camera_joint" type="fixed">
        <parent link="base_link"/>  <!-- Attach to base_link or another link -->
        <child link="camera_link"/>
        <origin xyz="-0.00032976124091513292491 -0.091578898488961058 0.3865718126789312592" rpy="6.3108872417680804303e-30 -2.9537602700216738211e-30 -3.141592653589793116" />
    </joint>
    
    <!-- Transmissions for rear wheels and steering joint -->
    <transmission name="rear_left_wheel_transmission">
        <type>transmission_interface/SimpleTransmission</type>
        <joint name="base_front_left_wheel_joint">
            <hardwareInterface>hardware_interface/VelocityJointInterface</hardwareInterface>
        </joint>
        <actuator name="rear_left_wheel_motor"/>
        <mechanicalReduction>1.0</mechanicalReduction>
    </transmission>

    <transmission name="rear_right_wheel_transmission">
        <type>transmission_interface/SimpleTransmission</type>
        <joint name="base_front_right_wheel_joint">
            <hardwareInterface>hardware_interface/VelocityJointInterface</hardwareInterface>
        </joint>
        <actuator name="rear_right_wheel_motor"/>
        <mechanicalReduction>1.0</mechanicalReduction>
    </transmission>

    <transmission name="steering_transmission">
        <type>transmission_interface/SimpleTransmission</type>
        <joint name="liigend_to_kere_joint">
            <hardwareInterface>hardware_interface/PositionJointInterface</hardwareInterface>
        </joint>
        <actuator name="steering_motor"/>
        <mechanicalReduction>1.0</mechanicalReduction>
    </transmission>
    
    <transmission name="steering_transmission">
        <type>transmission_interface/SimpleTransmission</type>
        <joint name="liigend_to_kere_joint">
            <hardwareInterface>hardware_interface/PositionJointInterface</hardwareInterface>
        </joint>
        <actuator name="steering_motor"/>
        <mechanicalReduction>1.0</mechanicalReduction>
    </transmission>
    
    
    
    <transmission name="front_left_wheel_transmission">
      <type>transmission_interface/SimpleTransmission</type>
      <joint name="front_left_wheel_joint"/>
      <actuator name="front_left_wheel_motor"/>
      <mechanicalReduction>1.0</mechanicalReduction>  <!-- Adjust if you have gearing -->
    </transmission>

    <transmission name="front_right_wheel_transmission">
      <type>transmission_interface/SimpleTransmission</type>
      <joint name="front_right_wheel_joint"/>
      <actuator name="front_right_wheel_motor"/>
      <mechanicalReduction>1.0</mechanicalReduction>
    </transmission>



    
</robot>

