<sdf version='1.7'>
  <model name='hermes'>
    <link name='base_footprint'>
      <inertial>
        <pose>0.259917 -0.001833 -0.170611 0 -0 0</pose>
        <mass>8</mass>
        <inertia>
          <ixx>3.95495</ixx>
          <ixy>0.0114364</ixy>
          <ixz>-1.43093</ixz>
          <iyy>5.57623</iyy>
          <iyz>0.0100932</iyz>
          <izz>4.12144</izz>
        </inertia>
      </inertial>
      <visual name='base_footprint_fixed_joint_lump__base_link_visual'>
        <pose>0.505754 -0.007177 0.122557 0 -0 0</pose>
        <geometry>
          <mesh>
            <scale>1 1 1</scale>
            <uri>/home/aleksmalm/Hermes/hermes_ws/src/hermes_urdf/urdf/kere.stl</uri>
          </mesh>
        </geometry>
      </visual>
      <visual name='base_footprint_fixed_joint_lump__ld19_visual_1'>
        <pose>1.03967 -0.007333 0.517557 0 0 -1.5708</pose>
        <geometry>
          <mesh>
            <scale>1 1 1</scale>
            <uri>/home/aleksmalm/Hermes/hermes_ws/src/hermes_urdf/urdf/ld19.stl</uri>
          </mesh>
        </geometry>
      </visual>
    </link>
    <joint name='base_rear_left_wheel_joint' type='revolute'>
      <pose relative_to='base_footprint'>0.066534 0.250323 0.132557 3.14159 0 -3.14159</pose>
      <parent>base_footprint</parent>
      <child>rear_left_wheel</child>
      <axis>
        <xyz>0 1 0</xyz>
        <limit>
          <lower>-1e+16</lower>
          <upper>1e+16</upper>
        </limit>
        <dynamics>
          <spring_reference>0</spring_reference>
          <spring_stiffness>0</spring_stiffness>
        </dynamics>
      </axis>
    </joint>
    <link name='rear_left_wheel'>
      <pose relative_to='base_rear_left_wheel_joint'>0 0 0 0 -0 0</pose>
      <inertial>
        <pose>0 0 0 0 -0 0</pose>
        <mass>1.5</mass>
        <inertia>
          <ixx>0.3</ixx>
          <ixy>0</ixy>
          <ixz>0</ixz>
          <iyy>0.3</iyy>
          <iyz>0</iyz>
          <izz>0.3</izz>
        </inertia>
      </inertial>
      <visual name='rear_left_wheel_visual'>
        <pose>0 0 0 0 -0 0</pose>
        <geometry>
          <mesh>
            <scale>1 1 1</scale>
            <uri>/home/aleksmalm/Hermes/hermes_ws/src/hermes_urdf/urdf/rehv.stl</uri>
          </mesh>
        </geometry>
      </visual>
    </link>
    <joint name='base_rear_right_wheel_joint' type='revolute'>
      <pose relative_to='base_footprint'>0.066534 -0.214677 0.132557 0 -0 0</pose>
      <parent>base_footprint</parent>
      <child>rear_right_wheel</child>
      <axis>
        <xyz>0 1 0</xyz>
        <limit>
          <lower>-1e+16</lower>
          <upper>1e+16</upper>
        </limit>
        <dynamics>
          <spring_reference>0</spring_reference>
          <spring_stiffness>0</spring_stiffness>
        </dynamics>
      </axis>
    </joint>
    <link name='rear_right_wheel'>
      <pose relative_to='base_rear_right_wheel_joint'>0 0 0 0 -0 0</pose>
      <inertial>
        <pose>0 0 0 0 -0 0</pose>
        <mass>1.5</mass>
        <inertia>
          <ixx>0.3</ixx>
          <ixy>0</ixy>
          <ixz>0</ixz>
          <iyy>0.3</iyy>
          <iyz>0</iyz>
          <izz>0.3</izz>
        </inertia>
      </inertial>
      <visual name='rear_right_wheel_visual'>
        <pose>0 0 0 0 -0 0</pose>
        <geometry>
          <mesh>
            <scale>1 1 1</scale>
            <uri>/home/aleksmalm/Hermes/hermes_ws/src/hermes_urdf/urdf/rehv.stl</uri>
          </mesh>
        </geometry>
      </visual>
    </link>
    <joint name='liigend_to_kere_joint' type='revolute'>
      <pose relative_to='base_footprint'>0.948334 -0.007177 0.127557 0 -0 -1.5708</pose>
      <parent>base_footprint</parent>
      <child>liigend</child>
      <axis>
        <xyz>0 0 1</xyz>
        <limit>
          <lower>-2e+16</lower>
          <upper>2e+16</upper>
        </limit>
        <dynamics>
          <spring_reference>0</spring_reference>
          <spring_stiffness>0</spring_stiffness>
        </dynamics>
      </axis>
    </joint>
    <link name='liigend'>
      <pose relative_to='liigend_to_kere_joint'>0 0 0 0 -0 0</pose>
      <inertial>
        <pose>0 0 0 0 -0 0</pose>
        <mass>3</mass>
        <inertia>
          <ixx>0.7</ixx>
          <ixy>0</ixy>
          <ixz>0</ixz>
          <iyy>0.7</iyy>
          <iyz>0</iyz>
          <izz>0.7</izz>
        </inertia>
      </inertial>
      <visual name='liigend_visual'>
        <pose>0 0 0 0 -0 0</pose>
        <geometry>
          <mesh>
            <scale>1 1 1</scale>
            <uri>/home/aleksmalm/Hermes/hermes_ws/src/hermes_urdf/urdf/liigend.stl</uri>
          </mesh>
        </geometry>
      </visual>
    </link>
    <joint name='base_front_left_wheel_joint' type='revolute'>
      <pose relative_to='liigend'>-0.302323 0 0 0 -0 0</pose>
      <parent>liigend</parent>
      <child>front_left_wheel</child>
      <axis>
        <xyz>1 0 0</xyz>
        <limit>
          <lower>-1e+16</lower>
          <upper>1e+16</upper>
        </limit>
        <dynamics>
          <spring_reference>0</spring_reference>
          <spring_stiffness>0</spring_stiffness>
        </dynamics>
      </axis>
    </joint>
    <link name='front_left_wheel'>
      <pose relative_to='base_front_left_wheel_joint'>0 0 0 0 -0 0</pose>
      <inertial>
        <pose>0 0 0 0 -0 0</pose>
        <mass>1.5</mass>
        <inertia>
          <ixx>0.3</ixx>
          <ixy>0</ixy>
          <ixz>0</ixz>
          <iyy>0.3</iyy>
          <iyz>0</iyz>
          <izz>0.3</izz>
        </inertia>
      </inertial>
      <visual name='front_left_wheel_visual'>
        <pose>0 0 0 0 -0 1.58</pose>
        <geometry>
          <mesh>
            <scale>1 1 1</scale>
            <uri>/home/aleksmalm/Hermes/hermes_ws/src/hermes_urdf/urdf/rehv.stl</uri>
          </mesh>
        </geometry>
      </visual>
    </link>
    <joint name='base_front_right_wheel_joint' type='revolute'>
      <pose relative_to='liigend'>0.252377 0 0 0 -0 0</pose>
      <parent>liigend</parent>
      <child>front_right_wheel</child>
      <axis>
        <xyz>1 0 0</xyz>
        <limit>
          <lower>-1e+16</lower>
          <upper>1e+16</upper>
        </limit>
        <dynamics>
          <spring_reference>0</spring_reference>
          <spring_stiffness>0</spring_stiffness>
        </dynamics>
      </axis>
    </joint>
    <link name='front_right_wheel'>
      <pose relative_to='base_front_right_wheel_joint'>0 0 0 0 -0 0</pose>
      <inertial>
        <pose>0 0 0 0 -0 0</pose>
        <mass>1.5</mass>
        <inertia>
          <ixx>0.3</ixx>
          <ixy>0</ixy>
          <ixz>0</ixz>
          <iyy>0.3</iyy>
          <iyz>0</iyz>
          <izz>0.3</izz>
        </inertia>
      </inertial>
      <visual name='front_right_wheel_visual'>
        <pose>0 0 0 0 -0 1.583</pose>
        <geometry>
          <mesh>
            <scale>1 1 1</scale>
            <uri>/home/aleksmalm/Hermes/hermes_ws/src/hermes_urdf/urdf/rehv.stl</uri>
          </mesh>
        </geometry>
      </visual>
    </link>
    <static>0</static>
    
  </model>
</sdf>
