<sdf version='1.9'>
  <world name='default'>
   <model name='hermes'>
     <link name='base_footprint'>
       <inertial>
         <pose>0.2599166496214255 -0.001833342422528454 -0.1706108119774088 0 0 0</pose>
         <mass>8</mass>
         <inertia>
           <ixx>3.954946257426446</ixx>
           <ixy>0.011436389281738169</ixy>
           <ixz>-1.430929661045067</ixz>
           <iyy>5.5762255439701738</iyy>
           <iyz>0.01009317431210814</iyz>
           <izz>4.1214406214767632</izz>
         </inertia>
       </inertial>
       <visual name='base_footprint_fixed_joint_lump__base_link_visual'>
         <pose>0.5057542042314841 -0.00717743037699722 0.1225567520903501 7.940934590483603e-23 -1.464425309870824e-15 1.554312234475186e-15</pose>
         <geometry>
           <mesh>
             <scale>1 1 1</scale>
             <uri>/home/hermes/Hermes/hermes_ws/src/hermes_urdf/urdf/kere.stl</uri>
           </mesh>
         </geometry>
         <material>
           <diffuse>0.769608 1 1 1</diffuse>
           <ambient>0.769608 1 1 1</ambient>
         </material>
       </visual>
       <visual name='base_footprint_fixed_joint_lump__ld19_visual_1'>
         <pose>1.039666598485702 -0.007333369690113816 0.5175567520903647 1.464425309870803e-15 7.940934447820008e-23 -1.570796326794897</pose>
         <geometry>
           <mesh>
             <scale>1 1 1</scale>
             <uri>/home/hermes/Hermes/hermes_ws/src/hermes_urdf/urdf/ld19.stl</uri>
           </mesh>
         </geometry>
         <material>
           <diffuse>0.289216 0.47549 0.882353 1</diffuse>
           <ambient>0.289216 0.47549 0.882353 1</ambient>
         </material>
       </visual>
     </link>
     <joint name='base_rear_left_wheel_joint' type='revolute'>
       <pose relative_to='base_footprint'>0.06653420423147499 0.2503225696230009 0.1325567520903497 3.141592653589793 1.866562460151128e-15 -3.141592653589793</pose>
       <parent>base_footprint</parent>
       <child>rear_left_wheel</child>
       <axis>
         <xyz>0 1 0</xyz>
         <limit>
           <lower>-10000000000000000</lower>
           <upper>10000000000000000</upper>
         </limit>
         <dynamics>
           <spring_reference>0</spring_reference>
           <spring_stiffness>0</spring_stiffness>
         </dynamics>
       </axis>
     </joint>
     <link name='rear_left_wheel'>
       <pose relative_to='base_rear_left_wheel_joint'>0 0 0 0 0 0</pose>
       <inertial>
         <pose>0 0 0 0 0 0</pose>
         <mass>1.5</mass>
         <inertia>
           <ixx>0.29999999999999999</ixx>
           <ixy>0</ixy>
           <ixz>0</ixz>
           <iyy>0.29999999999999999</iyy>
           <iyz>0</iyz>
           <izz>0.29999999999999999</izz>
         </inertia>
       </inertial>
       <visual name='rear_left_wheel_visual'>
         <pose>0 0 0 0 0 0</pose>
         <geometry>
           <mesh>
             <scale>1 1 1</scale>
             <uri>/home/hermes/Hermes/hermes_ws/src/hermes_urdf/urdf/rehv.stl</uri>
           </mesh>
         </geometry>
         <material>
           <diffuse>0.769608 1 1 1</diffuse>
           <ambient>0.769608 1 1 1</ambient>
         </material>
       </visual>
     </link>
     <joint name='base_rear_right_wheel_joint' type='revolute'>
       <pose relative_to='base_footprint'>0.06653420423147466 -0.2146774303769969 0.1325567520903498 3.361192324919048e-30 -1.86656246015113e-15 5.689893001203797e-16</pose>
       <parent>base_footprint</parent>
       <child>rear_right_wheel</child>
       <axis>
         <xyz>0 1 0</xyz>
         <limit>
           <lower>-10000000000000000</lower>
           <upper>10000000000000000</upper>
         </limit>
         <dynamics>
           <spring_reference>0</spring_reference>
           <spring_stiffness>0</spring_stiffness>
         </dynamics>
       </axis>
     </joint>
     <link name='rear_right_wheel'>
       <pose relative_to='base_rear_right_wheel_joint'>0 0 0 0 0 0</pose>
       <inertial>
         <pose>0 0 0 0 0 0</pose>
         <mass>1.5</mass>
         <inertia>
           <ixx>0.29999999999999999</ixx>
           <ixy>0</ixy>
           <ixz>0</ixz>
           <iyy>0.29999999999999999</iyy>
           <iyz>0</iyz>
           <izz>0.29999999999999999</izz>
         </inertia>
       </inertial>
       <visual name='rear_right_wheel_visual'>
         <pose>0 0 0 0 0 0</pose>
         <geometry>
           <mesh>
             <scale>1 1 1</scale>
             <uri>/home/hermes/Hermes/hermes_ws/src/hermes_urdf/urdf/rehv.stl</uri>
           </mesh>
         </geometry>
         <material>
           <diffuse>0.769608 1 1 1</diffuse>
           <ambient>0.769608 1 1 1</ambient>
         </material>
       </visual>
     </link>
     <joint name='liigend_to_kere_joint' type='revolute'>
       <pose relative_to='base_footprint'>0.9483341292917655 -0.007177430376996585 0.1275567520903587 2.268699310594816e-15 -6.135011666675779e-22 -1.570796326794839</pose>
       <parent>base_footprint</parent>
       <child>liigend</child>
       <axis>
         <xyz>0 0 1</xyz>
         <limit>
           <lower>-10000000000000000</lower>
           <upper>10000000000000000</upper>
         </limit>
         <dynamics>
           <spring_reference>0</spring_reference>
           <spring_stiffness>0</spring_stiffness>
         </dynamics>
       </axis>
     </joint>
     <link name='liigend'>
       <pose relative_to='liigend_to_kere_joint'>0 0 0 0 0 0</pose>
       <inertial>
         <pose>0 0 0 0 0 0</pose>
         <mass>3</mass>
         <inertia>
           <ixx>0.69999999999999996</ixx>
           <ixy>0</ixy>
           <ixz>0</ixz>
           <iyy>0.69999999999999996</iyy>
           <iyz>0</iyz>
           <izz>0.69999999999999996</izz>
         </inertia>
       </inertial>
       <visual name='liigend_visual'>
         <pose>0 0 0 0 0 0</pose>
         <geometry>
           <mesh>
             <scale>1 1 1</scale>
             <uri>/home/hermes/Hermes/hermes_ws/src/hermes_urdf/urdf/liigend.stl</uri>
           </mesh>
         </geometry>
         <material>
           <diffuse>0.769608 1 1 1</diffuse>
           <ambient>0.769608 1 1 1</ambient>
         </material>
       </visual>
     </link>
     <joint name='base_front_left_wheel_joint' type='revolute'>
       <pose relative_to='liigend'>-0.3023225696230035 0 0 0 0 0</pose>
       <parent>liigend</parent>
       <child>front_left_wheel</child>
       <axis>
         <xyz>1 0 0</xyz>
         <limit>
           <lower>-10000000000000000</lower>
           <upper>10000000000000000</upper>
         </limit>
         <dynamics>
           <spring_reference>0</spring_reference>
           <spring_stiffness>0</spring_stiffness>
         </dynamics>
       </axis>
     </joint>
     <link name='front_left_wheel'>
       <pose relative_to='base_front_left_wheel_joint'>0 0 0 0 0 0</pose>
       <inertial>
         <pose>0 0 0 0 0 0</pose>
         <mass>1.5</mass>
         <inertia>
           <ixx>0.29999999999999999</ixx>
           <ixy>0</ixy>
           <ixz>0</ixz>
           <iyy>0.29999999999999999</iyy>
           <iyz>0</iyz>
           <izz>0.29999999999999999</izz>
         </inertia>
       </inertial>
       <visual name='front_left_wheel_visual'>
         <pose>0 0 0 0 0 1.58</pose>
         <geometry>
           <mesh>
             <scale>1 1 1</scale>
             <uri>/home/hermes/Hermes/hermes_ws/src/hermes_urdf/urdf/rehv.stl</uri>
           </mesh>
         </geometry>
         <material>
           <diffuse>0.769608 1 1 1</diffuse>
           <ambient>0.769608 1 1 1</ambient>
         </material>
       </visual>
     </link>
     <joint name='base_front_right_wheel_joint' type='revolute'>
       <pose relative_to='liigend'>0.2523774303769967 0 0 0 0 0</pose>
       <parent>liigend</parent>
       <child>front_right_wheel</child>
       <axis>
         <xyz>1 0 0</xyz>
         <limit>
           <lower>-10000000000000000</lower>
           <upper>10000000000000000</upper>
         </limit>
         <dynamics>
           <spring_reference>0</spring_reference>
           <spring_stiffness>0</spring_stiffness>
         </dynamics>
       </axis>
     </joint>
     <link name='front_right_wheel'>
       <pose relative_to='base_front_right_wheel_joint'>0 0 0 0 0 0</pose>
       <inertial>
         <pose>0 0 0 0 0 0</pose>
         <mass>1.5</mass>
         <inertia>
           <ixx>0.29999999999999999</ixx>
           <ixy>0</ixy>
           <ixz>0</ixz>
           <iyy>0.29999999999999999</iyy>
           <iyz>0</iyz>
           <izz>0.29999999999999999</izz>
         </inertia>
       </inertial>
       <visual name='front_right_wheel_visual'>
         <pose>0 0 0 0 0 1.583</pose>
         <geometry>
           <mesh>
             <scale>1 1 1</scale>
             <uri>/home/hermes/Hermes/hermes_ws/src/hermes_urdf/urdf/rehv.stl</uri>
           </mesh>
         </geometry>
         <material>
           <diffuse>0.769608 1 1 1</diffuse>
           <ambient>0.769608 1 1 1</ambient>
         </material>
       </visual>
     </link>
     <plugin name='differential_drive_controller' filename='libgazebo_ros_diff_drive.so'>
       <updateRate>10</updateRate>
       <leftJoint>base_front_left_wheel_joint</leftJoint>
       <rightJoint>base_front_right_wheel_joint</rightJoint>
       <wheelSeparation>0.54</wheelSeparation>
       <wheelDiameter>0.254</wheelDiameter>
       <wheelAcceleration>1.0</wheelAcceleration>
       <wheelTorque>5</wheelTorque>
       <commandTopic>cmd_vel</commandTopic>
       <odometryTopic>odom</odometryTopic>
       <odometryFrame>odom</odometryFrame>
       <robotBaseFrame>base_footprint</robotBaseFrame>
       <odometrySource>1</odometrySource>
       <publishWheelTF>false</publishWheelTF>
       <publishOdom>true</publishOdom>
       <publishWheelJointState>true</publishWheelJointState>
       <legacyMode>false</legacyMode>
     </plugin>
     <frame name='base_lidar_joint' attached_to='base_link'>
       <pose>1.03967 -0.007333 0.997557 0 0 -1.5708</pose>
     </frame>
     <frame name='ld19' attached_to='base_lidar_joint'/>
     <frame name='base_joint' attached_to='base_footprint'>
       <pose>0 0 -0.48 0 -0 0</pose>
     </frame>
     <frame name='base_link' attached_to='base_joint'/>
   </model>
  </world>
</sdf>
